{"name": "home page shows a list of products", "status": "broken", "statusDetails": {"message": "google.api_core.exceptions.ResourceExhausted: 429 You exceeded your current quota, please check your plan and billing details. For more information on this error, head to: https://ai.google.dev/gemini-api/docs/rate-limits. [violations {\n  quota_metric: \"generativelanguage.googleapis.com/generate_content_free_tier_requests\"\n  quota_id: \"GenerateRequestsPerDayPerProjectPerModel-FreeTier\"\n  quota_dimensions {\n    key: \"model\"\n    value: \"gemini-2.0-flash\"\n  }\n  quota_dimensions {\n    key: \"location\"\n    value: \"global\"\n  }\n  quota_value: 1000\n}\n, links {\n  description: \"Learn more about Gemini API quotas\"\n  url: \"https://ai.google.dev/gemini-api/docs/rate-limits\"\n}\n, retry_delay {\n  seconds: 45\n}\n]\n", "trace": "  File \"/opt/hostedtoolcache/Python/3.11.12/x64/lib/python3.11/site-packages/behave/model.py\", line 1329, in run\n    match.run(runner.context)\n  File \"/opt/hostedtoolcache/Python/3.11.12/x64/lib/python3.11/site-packages/behave/matchers.py\", line 98, in run\n    self.func(context, *args, **kwargs)\n  File \"features/steps/common.py\", line 31, in step_impl\n    al.check(condition)\n  File \"/opt/hostedtoolcache/Python/3.11.12/x64/lib/python3.11/site-packages/alumnium/alumni.py\", line 102, in check\n    result = self.retrieval_agent.invoke(f\"Is the following true or false - {statement}\", vision)\n             ^^^^^^^^^^^^^^^^^^^^^^^^^^^^^^^^^^^^^^^^^^^^^^^^^^^^^^^^^^^^^^^^^^^^^^^^^^^^^^^^^^^^\n  File \"/opt/hostedtoolcache/Python/3.11.12/x64/lib/python3.11/site-packages/alumnium/agents/retriever_agent.py\", line 73, in invoke\n    message = self.chain.invoke(\n              ^^^^^^^^^^^^^^^^^^\n  File \"/opt/hostedtoolcache/Python/3.11.12/x64/lib/python3.11/site-packages/langchain_core/runnables/retry.py\", line 201, in invoke\n    return self._call_with_config(self._invoke, input, config, **kwargs)\n           ^^^^^^^^^^^^^^^^^^^^^^^^^^^^^^^^^^^^^^^^^^^^^^^^^^^^^^^^^^^^^\n  File \"/opt/hostedtoolcache/Python/3.11.12/x64/lib/python3.11/site-packages/langchain_core/runnables/base.py\", line 1940, in _call_with_config\n    context.run(\n  File \"/opt/hostedtoolcache/Python/3.11.12/x64/lib/python3.11/site-packages/langchain_core/runnables/config.py\", line 428, in call_func_with_variable_args\n    return func(input, **kwargs)  # type: ignore[call-arg]\n           ^^^^^^^^^^^^^^^^^^^^^\n  File \"/opt/hostedtoolcache/Python/3.11.12/x64/lib/python3.11/site-packages/langchain_core/runnables/retry.py\", line 186, in _invoke\n    for attempt in self._sync_retrying(reraise=True):\n  File \"/opt/hostedtoolcache/Python/3.11.12/x64/lib/python3.11/site-packages/tenacity/__init__.py\", line 445, in __iter__\n    do = self.iter(retry_state=retry_state)\n         ^^^^^^^^^^^^^^^^^^^^^^^^^^^^^^^^^^\n  File \"/opt/hostedtoolcache/Python/3.11.12/x64/lib/python3.11/site-packages/tenacity/__init__.py\", line 378, in iter\n    result = action(retry_state)\n             ^^^^^^^^^^^^^^^^^^^\n  File \"/opt/hostedtoolcache/Python/3.11.12/x64/lib/python3.11/site-packages/tenacity/__init__.py\", line 420, in exc_check\n    raise retry_exc.reraise()\n          ^^^^^^^^^^^^^^^^^^^\n  File \"/opt/hostedtoolcache/Python/3.11.12/x64/lib/python3.11/site-packages/tenacity/__init__.py\", line 187, in reraise\n    raise self.last_attempt.result()\n          ^^^^^^^^^^^^^^^^^^^^^^^^^^\n  File \"/opt/hostedtoolcache/Python/3.11.12/x64/lib/python3.11/concurrent/futures/_base.py\", line 449, in result\n    return self.__get_result()\n           ^^^^^^^^^^^^^^^^^^^\n  File \"/opt/hostedtoolcache/Python/3.11.12/x64/lib/python3.11/concurrent/futures/_base.py\", line 401, in __get_result\n    raise self._exception\n  File \"/opt/hostedtoolcache/Python/3.11.12/x64/lib/python3.11/site-packages/langchain_core/runnables/retry.py\", line 188, in _invoke\n    result = super().invoke(\n             ^^^^^^^^^^^^^^^\n  File \"/opt/hostedtoolcache/Python/3.11.12/x64/lib/python3.11/site-packages/langchain_core/runnables/base.py\", line 5431, in invoke\n    return self.bound.invoke(\n           ^^^^^^^^^^^^^^^^^^\n  File \"/opt/hostedtoolcache/Python/3.11.12/x64/lib/python3.11/site-packages/langchain_core/runnables/retry.py\", line 201, in invoke\n    return self._call_with_config(self._invoke, input, config, **kwargs)\n           ^^^^^^^^^^^^^^^^^^^^^^^^^^^^^^^^^^^^^^^^^^^^^^^^^^^^^^^^^^^^^\n  File \"/opt/hostedtoolcache/Python/3.11.12/x64/lib/python3.11/site-packages/langchain_core/runnables/base.py\", line 1940, in _call_with_config\n    context.run(\n  File \"/opt/hostedtoolcache/Python/3.11.12/x64/lib/python3.11/site-packages/langchain_core/runnables/config.py\", line 428, in call_func_with_variable_args\n    return func(input, **kwargs)  # type: ignore[call-arg]\n           ^^^^^^^^^^^^^^^^^^^^^\n  File \"/opt/hostedtoolcache/Python/3.11.12/x64/lib/python3.11/site-packages/langchain_core/runnables/retry.py\", line 186, in _invoke\n    for attempt in self._sync_retrying(reraise=True):\n  File \"/opt/hostedtoolcache/Python/3.11.12/x64/lib/python3.11/site-packages/tenacity/__init__.py\", line 445, in __iter__\n    do = self.iter(retry_state=retry_state)\n         ^^^^^^^^^^^^^^^^^^^^^^^^^^^^^^^^^^\n  File \"/opt/hostedtoolcache/Python/3.11.12/x64/lib/python3.11/site-packages/tenacity/__init__.py\", line 378, in iter\n    result = action(retry_state)\n             ^^^^^^^^^^^^^^^^^^^\n  File \"/opt/hostedtoolcache/Python/3.11.12/x64/lib/python3.11/site-packages/tenacity/__init__.py\", line 400, in <lambda>\n    self._add_action_func(lambda rs: rs.outcome.result())\n                                     ^^^^^^^^^^^^^^^^^^^\n  File \"/opt/hostedtoolcache/Python/3.11.12/x64/lib/python3.11/concurrent/futures/_base.py\", line 449, in result\n    return self.__get_result()\n           ^^^^^^^^^^^^^^^^^^^\n  File \"/opt/hostedtoolcache/Python/3.11.12/x64/lib/python3.11/concurrent/futures/_base.py\", line 401, in __get_result\n    raise self._exception\n  File \"/opt/hostedtoolcache/Python/3.11.12/x64/lib/python3.11/site-packages/langchain_core/runnables/retry.py\", line 188, in _invoke\n    result = super().invoke(\n             ^^^^^^^^^^^^^^^\n  File \"/opt/hostedtoolcache/Python/3.11.12/x64/lib/python3.11/site-packages/langchain_core/runnables/base.py\", line 5431, in invoke\n    return self.bound.invoke(\n           ^^^^^^^^^^^^^^^^^^\n  File \"/opt/hostedtoolcache/Python/3.11.12/x64/lib/python3.11/site-packages/langchain_core/runnables/base.py\", line 3045, in invoke\n    input_ = context.run(step.invoke, input_, config, **kwargs)\n             ^^^^^^^^^^^^^^^^^^^^^^^^^^^^^^^^^^^^^^^^^^^^^^^^^^\n  File \"/opt/hostedtoolcache/Python/3.11.12/x64/lib/python3.11/site-packages/langchain_core/runnables/base.py\", line 3774, in invoke\n    output = {key: future.result() for key, future in zip(steps, futures)}\n             ^^^^^^^^^^^^^^^^^^^^^^^^^^^^^^^^^^^^^^^^^^^^^^^^^^^^^^^^^^^^^\n  File \"/opt/hostedtoolcache/Python/3.11.12/x64/lib/python3.11/site-packages/langchain_core/runnables/base.py\", line 3774, in <dictcomp>\n    output = {key: future.result() for key, future in zip(steps, futures)}\n                   ^^^^^^^^^^^^^^^\n  File \"/opt/hostedtoolcache/Python/3.11.12/x64/lib/python3.11/concurrent/futures/_base.py\", line 456, in result\n    return self.__get_result()\n           ^^^^^^^^^^^^^^^^^^^\n  File \"/opt/hostedtoolcache/Python/3.11.12/x64/lib/python3.11/concurrent/futures/_base.py\", line 401, in __get_result\n    raise self._exception\n  File \"/opt/hostedtoolcache/Python/3.11.12/x64/lib/python3.11/concurrent/futures/thread.py\", line 58, in run\n    result = self.fn(*self.args, **self.kwargs)\n             ^^^^^^^^^^^^^^^^^^^^^^^^^^^^^^^^^^\n  File \"/opt/hostedtoolcache/Python/3.11.12/x64/lib/python3.11/site-packages/langchain_core/runnables/base.py\", line 3758, in _invoke_step\n    return context.run(\n           ^^^^^^^^^^^^\n  File \"/opt/hostedtoolcache/Python/3.11.12/x64/lib/python3.11/site-packages/langchain_core/runnables/base.py\", line 5431, in invoke\n    return self.bound.invoke(\n           ^^^^^^^^^^^^^^^^^^\n  File \"/opt/hostedtoolcache/Python/3.11.12/x64/lib/python3.11/site-packages/langchain_google_genai/chat_models.py\", line 1255, in invoke\n    return super().invoke(input, config, stop=stop, **kwargs)\n           ^^^^^^^^^^^^^^^^^^^^^^^^^^^^^^^^^^^^^^^^^^^^^^^^^^\n  File \"/opt/hostedtoolcache/Python/3.11.12/x64/lib/python3.11/site-packages/langchain_core/language_models/chat_models.py\", line 372, in invoke\n    self.generate_prompt(\n  File \"/opt/hostedtoolcache/Python/3.11.12/x64/lib/python3.11/site-packages/langchain_core/language_models/chat_models.py\", line 957, in generate_prompt\n    return self.generate(prompt_messages, stop=stop, callbacks=callbacks, **kwargs)\n           ^^^^^^^^^^^^^^^^^^^^^^^^^^^^^^^^^^^^^^^^^^^^^^^^^^^^^^^^^^^^^^^^^^^^^^^^\n  File \"/opt/hostedtoolcache/Python/3.11.12/x64/lib/python3.11/site-packages/langchain_core/language_models/chat_models.py\", line 776, in generate\n    self._generate_with_cache(\n  File \"/opt/hostedtoolcache/Python/3.11.12/x64/lib/python3.11/site-packages/langchain_core/language_models/chat_models.py\", line 1022, in _generate_with_cache\n    result = self._generate(\n             ^^^^^^^^^^^^^^^\n  File \"/opt/hostedtoolcache/Python/3.11.12/x64/lib/python3.11/site-packages/langchain_google_genai/chat_models.py\", line 1342, in _generate\n    response: GenerateContentResponse = _chat_with_retry(\n                                        ^^^^^^^^^^^^^^^^^\n  File \"/opt/hostedtoolcache/Python/3.11.12/x64/lib/python3.11/site-packages/langchain_google_genai/chat_models.py\", line 210, in _chat_with_retry\n    return _chat_with_retry(**kwargs)\n           ^^^^^^^^^^^^^^^^^^^^^^^^^^\n  File \"/opt/hostedtoolcache/Python/3.11.12/x64/lib/python3.11/site-packages/tenacity/__init__.py\", line 338, in wrapped_f\n    return copy(f, *args, **kw)\n           ^^^^^^^^^^^^^^^^^^^^\n  File \"/opt/hostedtoolcache/Python/3.11.12/x64/lib/python3.11/site-packages/tenacity/__init__.py\", line 477, in __call__\n    do = self.iter(retry_state=retry_state)\n         ^^^^^^^^^^^^^^^^^^^^^^^^^^^^^^^^^^\n  File \"/opt/hostedtoolcache/Python/3.11.12/x64/lib/python3.11/site-packages/tenacity/__init__.py\", line 378, in iter\n    result = action(retry_state)\n             ^^^^^^^^^^^^^^^^^^^\n  File \"/opt/hostedtoolcache/Python/3.11.12/x64/lib/python3.11/site-packages/tenacity/__init__.py\", line 420, in exc_check\n    raise retry_exc.reraise()\n          ^^^^^^^^^^^^^^^^^^^\n  File \"/opt/hostedtoolcache/Python/3.11.12/x64/lib/python3.11/site-packages/tenacity/__init__.py\", line 187, in reraise\n    raise self.last_attempt.result()\n          ^^^^^^^^^^^^^^^^^^^^^^^^^^\n  File \"/opt/hostedtoolcache/Python/3.11.12/x64/lib/python3.11/concurrent/futures/_base.py\", line 449, in result\n    return self.__get_result()\n           ^^^^^^^^^^^^^^^^^^^\n  File \"/opt/hostedtoolcache/Python/3.11.12/x64/lib/python3.11/concurrent/futures/_base.py\", line 401, in __get_result\n    raise self._exception\n  File \"/opt/hostedtoolcache/Python/3.11.12/x64/lib/python3.11/site-packages/tenacity/__init__.py\", line 480, in __call__\n    result = fn(*args, **kwargs)\n             ^^^^^^^^^^^^^^^^^^^\n  File \"/opt/hostedtoolcache/Python/3.11.12/x64/lib/python3.11/site-packages/langchain_google_genai/chat_models.py\", line 208, in _chat_with_retry\n    raise e\n  File \"/opt/hostedtoolcache/Python/3.11.12/x64/lib/python3.11/site-packages/langchain_google_genai/chat_models.py\", line 192, in _chat_with_retry\n    return generation_method(**kwargs)\n           ^^^^^^^^^^^^^^^^^^^^^^^^^^^\n  File \"/opt/hostedtoolcache/Python/3.11.12/x64/lib/python3.11/site-packages/google/ai/generativelanguage_v1beta/services/generative_service/client.py\", line 868, in generate_content\n    response = rpc(\n               ^^^^\n  File \"/opt/hostedtoolcache/Python/3.11.12/x64/lib/python3.11/site-packages/google/api_core/gapic_v1/method.py\", line 131, in __call__\n    return wrapped_func(*args, **kwargs)\n           ^^^^^^^^^^^^^^^^^^^^^^^^^^^^^\n  File \"/opt/hostedtoolcache/Python/3.11.12/x64/lib/python3.11/site-packages/google/api_core/retry/retry_unary.py\", line 294, in retry_wrapped_func\n    return retry_target(\n           ^^^^^^^^^^^^^\n  File \"/opt/hostedtoolcache/Python/3.11.12/x64/lib/python3.11/site-packages/google/api_core/retry/retry_unary.py\", line 156, in retry_target\n    next_sleep = _retry_error_helper(\n                 ^^^^^^^^^^^^^^^^^^^^\n  File \"/opt/hostedtoolcache/Python/3.11.12/x64/lib/python3.11/site-packages/google/api_core/retry/retry_base.py\", line 214, in _retry_error_helper\n    raise final_exc from source_exc\n  File \"/opt/hostedtoolcache/Python/3.11.12/x64/lib/python3.11/site-packages/google/api_core/retry/retry_unary.py\", line 147, in retry_target\n    result = target()\n             ^^^^^^^^\n  File \"/opt/hostedtoolcache/Python/3.11.12/x64/lib/python3.11/site-packages/google/api_core/timeout.py\", line 130, in func_with_timeout\n    return func(*args, **kwargs)\n           ^^^^^^^^^^^^^^^^^^^^^\n  File \"/opt/hostedtoolcache/Python/3.11.12/x64/lib/python3.11/site-packages/google/api_core/grpc_helpers.py\", line 78, in error_remapped_callable\n    raise exceptions.from_grpc_error(exc) from exc\n"}, "steps": [{"name": "Given I am on the home page", "status": "passed", "start": 1750544052446, "stop": 1750544054342}, {"name": "Then \"there is a heading 'Shop'\"", "status": "broken", "statusDetails": {"message": "google.api_core.exceptions.ResourceExhausted: 429 You exceeded your current quota, please check your plan and billing details. For more information on this error, head to: https://ai.google.dev/gemini-api/docs/rate-limits. [violations {\n  quota_metric: \"generativelanguage.googleapis.com/generate_content_free_tier_requests\"\n  quota_id: \"GenerateRequestsPerDayPerProjectPerModel-FreeTier\"\n  quota_dimensions {\n    key: \"model\"\n    value: \"gemini-2.0-flash\"\n  }\n  quota_dimensions {\n    key: \"location\"\n    value: \"global\"\n  }\n  quota_value: 1000\n}\n, links {\n  description: \"Learn more about Gemini API quotas\"\n  url: \"https://ai.google.dev/gemini-api/docs/rate-limits\"\n}\n, retry_delay {\n  seconds: 45\n}\n]\n", "trace": "  File \"/opt/hostedtoolcache/Python/3.11.12/x64/lib/python3.11/site-packages/behave/model.py\", line 1329, in run\n    match.run(runner.context)\n  File \"/opt/hostedtoolcache/Python/3.11.12/x64/lib/python3.11/site-packages/behave/matchers.py\", line 98, in run\n    self.func(context, *args, **kwargs)\n  File \"features/steps/common.py\", line 31, in step_impl\n    al.check(condition)\n  File \"/opt/hostedtoolcache/Python/3.11.12/x64/lib/python3.11/site-packages/alumnium/alumni.py\", line 102, in check\n    result = self.retrieval_agent.invoke(f\"Is the following true or false - {statement}\", vision)\n             ^^^^^^^^^^^^^^^^^^^^^^^^^^^^^^^^^^^^^^^^^^^^^^^^^^^^^^^^^^^^^^^^^^^^^^^^^^^^^^^^^^^^\n  File \"/opt/hostedtoolcache/Python/3.11.12/x64/lib/python3.11/site-packages/alumnium/agents/retriever_agent.py\", line 73, in invoke\n    message = self.chain.invoke(\n              ^^^^^^^^^^^^^^^^^^\n  File \"/opt/hostedtoolcache/Python/3.11.12/x64/lib/python3.11/site-packages/langchain_core/runnables/retry.py\", line 201, in invoke\n    return self._call_with_config(self._invoke, input, config, **kwargs)\n           ^^^^^^^^^^^^^^^^^^^^^^^^^^^^^^^^^^^^^^^^^^^^^^^^^^^^^^^^^^^^^\n  File \"/opt/hostedtoolcache/Python/3.11.12/x64/lib/python3.11/site-packages/langchain_core/runnables/base.py\", line 1940, in _call_with_config\n    context.run(\n  File \"/opt/hostedtoolcache/Python/3.11.12/x64/lib/python3.11/site-packages/langchain_core/runnables/config.py\", line 428, in call_func_with_variable_args\n    return func(input, **kwargs)  # type: ignore[call-arg]\n           ^^^^^^^^^^^^^^^^^^^^^\n  File \"/opt/hostedtoolcache/Python/3.11.12/x64/lib/python3.11/site-packages/langchain_core/runnables/retry.py\", line 186, in _invoke\n    for attempt in self._sync_retrying(reraise=True):\n  File \"/opt/hostedtoolcache/Python/3.11.12/x64/lib/python3.11/site-packages/tenacity/__init__.py\", line 445, in __iter__\n    do = self.iter(retry_state=retry_state)\n         ^^^^^^^^^^^^^^^^^^^^^^^^^^^^^^^^^^\n  File \"/opt/hostedtoolcache/Python/3.11.12/x64/lib/python3.11/site-packages/tenacity/__init__.py\", line 378, in iter\n    result = action(retry_state)\n             ^^^^^^^^^^^^^^^^^^^\n  File \"/opt/hostedtoolcache/Python/3.11.12/x64/lib/python3.11/site-packages/tenacity/__init__.py\", line 420, in exc_check\n    raise retry_exc.reraise()\n          ^^^^^^^^^^^^^^^^^^^\n  File \"/opt/hostedtoolcache/Python/3.11.12/x64/lib/python3.11/site-packages/tenacity/__init__.py\", line 187, in reraise\n    raise self.last_attempt.result()\n          ^^^^^^^^^^^^^^^^^^^^^^^^^^\n  File \"/opt/hostedtoolcache/Python/3.11.12/x64/lib/python3.11/concurrent/futures/_base.py\", line 449, in result\n    return self.__get_result()\n           ^^^^^^^^^^^^^^^^^^^\n  File \"/opt/hostedtoolcache/Python/3.11.12/x64/lib/python3.11/concurrent/futures/_base.py\", line 401, in __get_result\n    raise self._exception\n  File \"/opt/hostedtoolcache/Python/3.11.12/x64/lib/python3.11/site-packages/langchain_core/runnables/retry.py\", line 188, in _invoke\n    result = super().invoke(\n             ^^^^^^^^^^^^^^^\n  File \"/opt/hostedtoolcache/Python/3.11.12/x64/lib/python3.11/site-packages/langchain_core/runnables/base.py\", line 5431, in invoke\n    return self.bound.invoke(\n           ^^^^^^^^^^^^^^^^^^\n  File \"/opt/hostedtoolcache/Python/3.11.12/x64/lib/python3.11/site-packages/langchain_core/runnables/retry.py\", line 201, in invoke\n    return self._call_with_config(self._invoke, input, config, **kwargs)\n           ^^^^^^^^^^^^^^^^^^^^^^^^^^^^^^^^^^^^^^^^^^^^^^^^^^^^^^^^^^^^^\n  File \"/opt/hostedtoolcache/Python/3.11.12/x64/lib/python3.11/site-packages/langchain_core/runnables/base.py\", line 1940, in _call_with_config\n    context.run(\n  File \"/opt/hostedtoolcache/Python/3.11.12/x64/lib/python3.11/site-packages/langchain_core/runnables/config.py\", line 428, in call_func_with_variable_args\n    return func(input, **kwargs)  # type: ignore[call-arg]\n           ^^^^^^^^^^^^^^^^^^^^^\n  File \"/opt/hostedtoolcache/Python/3.11.12/x64/lib/python3.11/site-packages/langchain_core/runnables/retry.py\", line 186, in _invoke\n    for attempt in self._sync_retrying(reraise=True):\n  File \"/opt/hostedtoolcache/Python/3.11.12/x64/lib/python3.11/site-packages/tenacity/__init__.py\", line 445, in __iter__\n    do = self.iter(retry_state=retry_state)\n         ^^^^^^^^^^^^^^^^^^^^^^^^^^^^^^^^^^\n  File \"/opt/hostedtoolcache/Python/3.11.12/x64/lib/python3.11/site-packages/tenacity/__init__.py\", line 378, in iter\n    result = action(retry_state)\n             ^^^^^^^^^^^^^^^^^^^\n  File \"/opt/hostedtoolcache/Python/3.11.12/x64/lib/python3.11/site-packages/tenacity/__init__.py\", line 400, in <lambda>\n    self._add_action_func(lambda rs: rs.outcome.result())\n                                     ^^^^^^^^^^^^^^^^^^^\n  File \"/opt/hostedtoolcache/Python/3.11.12/x64/lib/python3.11/concurrent/futures/_base.py\", line 449, in result\n    return self.__get_result()\n           ^^^^^^^^^^^^^^^^^^^\n  File \"/opt/hostedtoolcache/Python/3.11.12/x64/lib/python3.11/concurrent/futures/_base.py\", line 401, in __get_result\n    raise self._exception\n  File \"/opt/hostedtoolcache/Python/3.11.12/x64/lib/python3.11/site-packages/langchain_core/runnables/retry.py\", line 188, in _invoke\n    result = super().invoke(\n             ^^^^^^^^^^^^^^^\n  File \"/opt/hostedtoolcache/Python/3.11.12/x64/lib/python3.11/site-packages/langchain_core/runnables/base.py\", line 5431, in invoke\n    return self.bound.invoke(\n           ^^^^^^^^^^^^^^^^^^\n  File \"/opt/hostedtoolcache/Python/3.11.12/x64/lib/python3.11/site-packages/langchain_core/runnables/base.py\", line 3045, in invoke\n    input_ = context.run(step.invoke, input_, config, **kwargs)\n             ^^^^^^^^^^^^^^^^^^^^^^^^^^^^^^^^^^^^^^^^^^^^^^^^^^\n  File \"/opt/hostedtoolcache/Python/3.11.12/x64/lib/python3.11/site-packages/langchain_core/runnables/base.py\", line 3774, in invoke\n    output = {key: future.result() for key, future in zip(steps, futures)}\n             ^^^^^^^^^^^^^^^^^^^^^^^^^^^^^^^^^^^^^^^^^^^^^^^^^^^^^^^^^^^^^\n  File \"/opt/hostedtoolcache/Python/3.11.12/x64/lib/python3.11/site-packages/langchain_core/runnables/base.py\", line 3774, in <dictcomp>\n    output = {key: future.result() for key, future in zip(steps, futures)}\n                   ^^^^^^^^^^^^^^^\n  File \"/opt/hostedtoolcache/Python/3.11.12/x64/lib/python3.11/concurrent/futures/_base.py\", line 456, in result\n    return self.__get_result()\n           ^^^^^^^^^^^^^^^^^^^\n  File \"/opt/hostedtoolcache/Python/3.11.12/x64/lib/python3.11/concurrent/futures/_base.py\", line 401, in __get_result\n    raise self._exception\n  File \"/opt/hostedtoolcache/Python/3.11.12/x64/lib/python3.11/concurrent/futures/thread.py\", line 58, in run\n    result = self.fn(*self.args, **self.kwargs)\n             ^^^^^^^^^^^^^^^^^^^^^^^^^^^^^^^^^^\n  File \"/opt/hostedtoolcache/Python/3.11.12/x64/lib/python3.11/site-packages/langchain_core/runnables/base.py\", line 3758, in _invoke_step\n    return context.run(\n           ^^^^^^^^^^^^\n  File \"/opt/hostedtoolcache/Python/3.11.12/x64/lib/python3.11/site-packages/langchain_core/runnables/base.py\", line 5431, in invoke\n    return self.bound.invoke(\n           ^^^^^^^^^^^^^^^^^^\n  File \"/opt/hostedtoolcache/Python/3.11.12/x64/lib/python3.11/site-packages/langchain_google_genai/chat_models.py\", line 1255, in invoke\n    return super().invoke(input, config, stop=stop, **kwargs)\n           ^^^^^^^^^^^^^^^^^^^^^^^^^^^^^^^^^^^^^^^^^^^^^^^^^^\n  File \"/opt/hostedtoolcache/Python/3.11.12/x64/lib/python3.11/site-packages/langchain_core/language_models/chat_models.py\", line 372, in invoke\n    self.generate_prompt(\n  File \"/opt/hostedtoolcache/Python/3.11.12/x64/lib/python3.11/site-packages/langchain_core/language_models/chat_models.py\", line 957, in generate_prompt\n    return self.generate(prompt_messages, stop=stop, callbacks=callbacks, **kwargs)\n           ^^^^^^^^^^^^^^^^^^^^^^^^^^^^^^^^^^^^^^^^^^^^^^^^^^^^^^^^^^^^^^^^^^^^^^^^\n  File \"/opt/hostedtoolcache/Python/3.11.12/x64/lib/python3.11/site-packages/langchain_core/language_models/chat_models.py\", line 776, in generate\n    self._generate_with_cache(\n  File \"/opt/hostedtoolcache/Python/3.11.12/x64/lib/python3.11/site-packages/langchain_core/language_models/chat_models.py\", line 1022, in _generate_with_cache\n    result = self._generate(\n             ^^^^^^^^^^^^^^^\n  File \"/opt/hostedtoolcache/Python/3.11.12/x64/lib/python3.11/site-packages/langchain_google_genai/chat_models.py\", line 1342, in _generate\n    response: GenerateContentResponse = _chat_with_retry(\n                                        ^^^^^^^^^^^^^^^^^\n  File \"/opt/hostedtoolcache/Python/3.11.12/x64/lib/python3.11/site-packages/langchain_google_genai/chat_models.py\", line 210, in _chat_with_retry\n    return _chat_with_retry(**kwargs)\n           ^^^^^^^^^^^^^^^^^^^^^^^^^^\n  File \"/opt/hostedtoolcache/Python/3.11.12/x64/lib/python3.11/site-packages/tenacity/__init__.py\", line 338, in wrapped_f\n    return copy(f, *args, **kw)\n           ^^^^^^^^^^^^^^^^^^^^\n  File \"/opt/hostedtoolcache/Python/3.11.12/x64/lib/python3.11/site-packages/tenacity/__init__.py\", line 477, in __call__\n    do = self.iter(retry_state=retry_state)\n         ^^^^^^^^^^^^^^^^^^^^^^^^^^^^^^^^^^\n  File \"/opt/hostedtoolcache/Python/3.11.12/x64/lib/python3.11/site-packages/tenacity/__init__.py\", line 378, in iter\n    result = action(retry_state)\n             ^^^^^^^^^^^^^^^^^^^\n  File \"/opt/hostedtoolcache/Python/3.11.12/x64/lib/python3.11/site-packages/tenacity/__init__.py\", line 420, in exc_check\n    raise retry_exc.reraise()\n          ^^^^^^^^^^^^^^^^^^^\n  File \"/opt/hostedtoolcache/Python/3.11.12/x64/lib/python3.11/site-packages/tenacity/__init__.py\", line 187, in reraise\n    raise self.last_attempt.result()\n          ^^^^^^^^^^^^^^^^^^^^^^^^^^\n  File \"/opt/hostedtoolcache/Python/3.11.12/x64/lib/python3.11/concurrent/futures/_base.py\", line 449, in result\n    return self.__get_result()\n           ^^^^^^^^^^^^^^^^^^^\n  File \"/opt/hostedtoolcache/Python/3.11.12/x64/lib/python3.11/concurrent/futures/_base.py\", line 401, in __get_result\n    raise self._exception\n  File \"/opt/hostedtoolcache/Python/3.11.12/x64/lib/python3.11/site-packages/tenacity/__init__.py\", line 480, in __call__\n    result = fn(*args, **kwargs)\n             ^^^^^^^^^^^^^^^^^^^\n  File \"/opt/hostedtoolcache/Python/3.11.12/x64/lib/python3.11/site-packages/langchain_google_genai/chat_models.py\", line 208, in _chat_with_retry\n    raise e\n  File \"/opt/hostedtoolcache/Python/3.11.12/x64/lib/python3.11/site-packages/langchain_google_genai/chat_models.py\", line 192, in _chat_with_retry\n    return generation_method(**kwargs)\n           ^^^^^^^^^^^^^^^^^^^^^^^^^^^\n  File \"/opt/hostedtoolcache/Python/3.11.12/x64/lib/python3.11/site-packages/google/ai/generativelanguage_v1beta/services/generative_service/client.py\", line 868, in generate_content\n    response = rpc(\n               ^^^^\n  File \"/opt/hostedtoolcache/Python/3.11.12/x64/lib/python3.11/site-packages/google/api_core/gapic_v1/method.py\", line 131, in __call__\n    return wrapped_func(*args, **kwargs)\n           ^^^^^^^^^^^^^^^^^^^^^^^^^^^^^\n  File \"/opt/hostedtoolcache/Python/3.11.12/x64/lib/python3.11/site-packages/google/api_core/retry/retry_unary.py\", line 294, in retry_wrapped_func\n    return retry_target(\n           ^^^^^^^^^^^^^\n  File \"/opt/hostedtoolcache/Python/3.11.12/x64/lib/python3.11/site-packages/google/api_core/retry/retry_unary.py\", line 156, in retry_target\n    next_sleep = _retry_error_helper(\n                 ^^^^^^^^^^^^^^^^^^^^\n  File \"/opt/hostedtoolcache/Python/3.11.12/x64/lib/python3.11/site-packages/google/api_core/retry/retry_base.py\", line 214, in _retry_error_helper\n    raise final_exc from source_exc\n  File \"/opt/hostedtoolcache/Python/3.11.12/x64/lib/python3.11/site-packages/google/api_core/retry/retry_unary.py\", line 147, in retry_target\n    result = target()\n             ^^^^^^^^\n  File \"/opt/hostedtoolcache/Python/3.11.12/x64/lib/python3.11/site-packages/google/api_core/timeout.py\", line 130, in func_with_timeout\n    return func(*args, **kwargs)\n           ^^^^^^^^^^^^^^^^^^^^^\n  File \"/opt/hostedtoolcache/Python/3.11.12/x64/lib/python3.11/site-packages/google/api_core/grpc_helpers.py\", line 78, in error_remapped_callable\n    raise exceptions.from_grpc_error(exc) from exc\n"}, "start": 1750544054342, "stop": 1750544594836}, {"name": "And \"there is a list of products\"", "status": "skipped", "start": 1750544619001, "stop": 1750544619001}], "attachments": [{"name": "Screenshot", "source": "68cae28a-431a-4ee4-a9c8-28f25d922a34-attachment.png", "type": "image/png"}, {"name": "Playwright Trace", "source": "4112dc84-56b2-4fc5-b772-04d61cff9d93-attachment.attach"}, {"name": "Video", "source": "9ebf9a17-67a6-495e-8db6-1866971b1e80-attachment.webm", "type": "video/webm"}], "start": 1750544052310, "stop": 1750544619001, "uuid": "63f45e3d-0b46-4ce3-acbd-8352cb53c0bf", "historyId": "608ec6e19c8e29d924e9ec2e2e6deb45", "fullName": "home page: home page shows a list of products", "labels": [{"name": "severity", "value": "normal"}, {"name": "feature", "value": "home page"}, {"name": "framework", "value": "behave"}, {"name": "language", "value": "cpython3"}]}