{"uid":"b9da68a866cbb8f3","name":"cart page item quantity can be increased","fullName":"cart page: cart page item quantity can be increased","historyId":"6ccb28b3d8fc93ee69898d35707a7705","time":{"start":1750619202398,"stop":1750620333518,"duration":1131120},"status":"broken","statusMessage":"google.api_core.exceptions.ResourceExhausted: 429 You exceeded your current quota, please check your plan and billing details. For more information on this error, head to: https://ai.google.dev/gemini-api/docs/rate-limits. [violations {\n  quota_metric: \"generativelanguage.googleapis.com/generate_content_free_tier_requests\"\n  quota_id: \"GenerateRequestsPerDayPerProjectPerModel-FreeTier\"\n  quota_dimensions {\n    key: \"model\"\n    value: \"gemini-2.0-flash\"\n  }\n  quota_dimensions {\n    key: \"location\"\n    value: \"global\"\n  }\n  quota_value: 1000\n}\n, links {\n  description: \"Learn more about Gemini API quotas\"\n  url: \"https://ai.google.dev/gemini-api/docs/rate-limits\"\n}\n, retry_delay {\n  seconds: 18\n}\n]\n","statusTrace":"  File \"/opt/hostedtoolcache/Python/3.11.12/x64/lib/python3.11/site-packages/behave/model.py\", line 1329, in run\n    match.run(runner.context)\n  File \"/opt/hostedtoolcache/Python/3.11.12/x64/lib/python3.11/site-packages/behave/matchers.py\", line 98, in run\n    self.func(context, *args, **kwargs)\n  File \"features/steps/common.py\", line 20, in step_impl\n    al.do(instruction)\n  File \"/opt/hostedtoolcache/Python/3.11.12/x64/lib/python3.11/site-packages/decorator.py\", line 235, in fun\n    return caller(func, *(extras + args), **kw)\n           ^^^^^^^^^^^^^^^^^^^^^^^^^^^^^^^^^^^^\n  File \"/opt/hostedtoolcache/Python/3.11.12/x64/lib/python3.11/site-packages/retry/api.py\", line 90, in retry_decorator\n    return __retry_internal(partial(f, *args, **kwargs), exceptions, tries, delay, max_delay, backoff, jitter,\n           ^^^^^^^^^^^^^^^^^^^^^^^^^^^^^^^^^^^^^^^^^^^^^^^^^^^^^^^^^^^^^^^^^^^^^^^^^^^^^^^^^^^^^^^^^^^^^^^^^^^\n  File \"/opt/hostedtoolcache/Python/3.11.12/x64/lib/python3.11/site-packages/retry/api.py\", line 35, in __retry_internal\n    return f()\n           ^^^\n  File \"/opt/hostedtoolcache/Python/3.11.12/x64/lib/python3.11/site-packages/alumnium/alumni.py\", line 84, in do\n    steps = self.planner_agent.invoke(goal)\n            ^^^^^^^^^^^^^^^^^^^^^^^^^^^^^^^\n  File \"/opt/hostedtoolcache/Python/3.11.12/x64/lib/python3.11/site-packages/alumnium/agents/planner_agent.py\", line 54, in invoke\n    message = self.chain.invoke({\"goal\": goal, \"aria\": aria.to_xml()})\n              ^^^^^^^^^^^^^^^^^^^^^^^^^^^^^^^^^^^^^^^^^^^^^^^^^^^^^^^^\n  File \"/opt/hostedtoolcache/Python/3.11.12/x64/lib/python3.11/site-packages/langchain_core/runnables/base.py\", line 3047, in invoke\n    input_ = context.run(step.invoke, input_, config)\n             ^^^^^^^^^^^^^^^^^^^^^^^^^^^^^^^^^^^^^^^^\n  File \"/opt/hostedtoolcache/Python/3.11.12/x64/lib/python3.11/site-packages/langchain_core/runnables/retry.py\", line 201, in invoke\n    return self._call_with_config(self._invoke, input, config, **kwargs)\n           ^^^^^^^^^^^^^^^^^^^^^^^^^^^^^^^^^^^^^^^^^^^^^^^^^^^^^^^^^^^^^\n  File \"/opt/hostedtoolcache/Python/3.11.12/x64/lib/python3.11/site-packages/langchain_core/runnables/base.py\", line 1940, in _call_with_config\n    context.run(\n  File \"/opt/hostedtoolcache/Python/3.11.12/x64/lib/python3.11/site-packages/langchain_core/runnables/config.py\", line 428, in call_func_with_variable_args\n    return func(input, **kwargs)  # type: ignore[call-arg]\n           ^^^^^^^^^^^^^^^^^^^^^\n  File \"/opt/hostedtoolcache/Python/3.11.12/x64/lib/python3.11/site-packages/langchain_core/runnables/retry.py\", line 186, in _invoke\n    for attempt in self._sync_retrying(reraise=True):\n  File \"/opt/hostedtoolcache/Python/3.11.12/x64/lib/python3.11/site-packages/tenacity/__init__.py\", line 445, in __iter__\n    do = self.iter(retry_state=retry_state)\n         ^^^^^^^^^^^^^^^^^^^^^^^^^^^^^^^^^^\n  File \"/opt/hostedtoolcache/Python/3.11.12/x64/lib/python3.11/site-packages/tenacity/__init__.py\", line 378, in iter\n    result = action(retry_state)\n             ^^^^^^^^^^^^^^^^^^^\n  File \"/opt/hostedtoolcache/Python/3.11.12/x64/lib/python3.11/site-packages/tenacity/__init__.py\", line 420, in exc_check\n    raise retry_exc.reraise()\n          ^^^^^^^^^^^^^^^^^^^\n  File \"/opt/hostedtoolcache/Python/3.11.12/x64/lib/python3.11/site-packages/tenacity/__init__.py\", line 187, in reraise\n    raise self.last_attempt.result()\n          ^^^^^^^^^^^^^^^^^^^^^^^^^^\n  File \"/opt/hostedtoolcache/Python/3.11.12/x64/lib/python3.11/concurrent/futures/_base.py\", line 449, in result\n    return self.__get_result()\n           ^^^^^^^^^^^^^^^^^^^\n  File \"/opt/hostedtoolcache/Python/3.11.12/x64/lib/python3.11/concurrent/futures/_base.py\", line 401, in __get_result\n    raise self._exception\n  File \"/opt/hostedtoolcache/Python/3.11.12/x64/lib/python3.11/site-packages/langchain_core/runnables/retry.py\", line 188, in _invoke\n    result = super().invoke(\n             ^^^^^^^^^^^^^^^\n  File \"/opt/hostedtoolcache/Python/3.11.12/x64/lib/python3.11/site-packages/langchain_core/runnables/base.py\", line 5431, in invoke\n    return self.bound.invoke(\n           ^^^^^^^^^^^^^^^^^^\n  File \"/opt/hostedtoolcache/Python/3.11.12/x64/lib/python3.11/site-packages/langchain_core/runnables/retry.py\", line 201, in invoke\n    return self._call_with_config(self._invoke, input, config, **kwargs)\n           ^^^^^^^^^^^^^^^^^^^^^^^^^^^^^^^^^^^^^^^^^^^^^^^^^^^^^^^^^^^^^\n  File \"/opt/hostedtoolcache/Python/3.11.12/x64/lib/python3.11/site-packages/langchain_core/runnables/base.py\", line 1940, in _call_with_config\n    context.run(\n  File \"/opt/hostedtoolcache/Python/3.11.12/x64/lib/python3.11/site-packages/langchain_core/runnables/config.py\", line 428, in call_func_with_variable_args\n    return func(input, **kwargs)  # type: ignore[call-arg]\n           ^^^^^^^^^^^^^^^^^^^^^\n  File \"/opt/hostedtoolcache/Python/3.11.12/x64/lib/python3.11/site-packages/langchain_core/runnables/retry.py\", line 186, in _invoke\n    for attempt in self._sync_retrying(reraise=True):\n  File \"/opt/hostedtoolcache/Python/3.11.12/x64/lib/python3.11/site-packages/tenacity/__init__.py\", line 445, in __iter__\n    do = self.iter(retry_state=retry_state)\n         ^^^^^^^^^^^^^^^^^^^^^^^^^^^^^^^^^^\n  File \"/opt/hostedtoolcache/Python/3.11.12/x64/lib/python3.11/site-packages/tenacity/__init__.py\", line 378, in iter\n    result = action(retry_state)\n             ^^^^^^^^^^^^^^^^^^^\n  File \"/opt/hostedtoolcache/Python/3.11.12/x64/lib/python3.11/site-packages/tenacity/__init__.py\", line 400, in <lambda>\n    self._add_action_func(lambda rs: rs.outcome.result())\n                                     ^^^^^^^^^^^^^^^^^^^\n  File \"/opt/hostedtoolcache/Python/3.11.12/x64/lib/python3.11/concurrent/futures/_base.py\", line 449, in result\n    return self.__get_result()\n           ^^^^^^^^^^^^^^^^^^^\n  File \"/opt/hostedtoolcache/Python/3.11.12/x64/lib/python3.11/concurrent/futures/_base.py\", line 401, in __get_result\n    raise self._exception\n  File \"/opt/hostedtoolcache/Python/3.11.12/x64/lib/python3.11/site-packages/langchain_core/runnables/retry.py\", line 188, in _invoke\n    result = super().invoke(\n             ^^^^^^^^^^^^^^^\n  File \"/opt/hostedtoolcache/Python/3.11.12/x64/lib/python3.11/site-packages/langchain_core/runnables/base.py\", line 5431, in invoke\n    return self.bound.invoke(\n           ^^^^^^^^^^^^^^^^^^\n  File \"/opt/hostedtoolcache/Python/3.11.12/x64/lib/python3.11/site-packages/langchain_google_genai/chat_models.py\", line 1255, in invoke\n    return super().invoke(input, config, stop=stop, **kwargs)\n           ^^^^^^^^^^^^^^^^^^^^^^^^^^^^^^^^^^^^^^^^^^^^^^^^^^\n  File \"/opt/hostedtoolcache/Python/3.11.12/x64/lib/python3.11/site-packages/langchain_core/language_models/chat_models.py\", line 372, in invoke\n    self.generate_prompt(\n  File \"/opt/hostedtoolcache/Python/3.11.12/x64/lib/python3.11/site-packages/langchain_core/language_models/chat_models.py\", line 957, in generate_prompt\n    return self.generate(prompt_messages, stop=stop, callbacks=callbacks, **kwargs)\n           ^^^^^^^^^^^^^^^^^^^^^^^^^^^^^^^^^^^^^^^^^^^^^^^^^^^^^^^^^^^^^^^^^^^^^^^^\n  File \"/opt/hostedtoolcache/Python/3.11.12/x64/lib/python3.11/site-packages/langchain_core/language_models/chat_models.py\", line 776, in generate\n    self._generate_with_cache(\n  File \"/opt/hostedtoolcache/Python/3.11.12/x64/lib/python3.11/site-packages/langchain_core/language_models/chat_models.py\", line 1022, in _generate_with_cache\n    result = self._generate(\n             ^^^^^^^^^^^^^^^\n  File \"/opt/hostedtoolcache/Python/3.11.12/x64/lib/python3.11/site-packages/langchain_google_genai/chat_models.py\", line 1342, in _generate\n    response: GenerateContentResponse = _chat_with_retry(\n                                        ^^^^^^^^^^^^^^^^^\n  File \"/opt/hostedtoolcache/Python/3.11.12/x64/lib/python3.11/site-packages/langchain_google_genai/chat_models.py\", line 210, in _chat_with_retry\n    return _chat_with_retry(**kwargs)\n           ^^^^^^^^^^^^^^^^^^^^^^^^^^\n  File \"/opt/hostedtoolcache/Python/3.11.12/x64/lib/python3.11/site-packages/tenacity/__init__.py\", line 338, in wrapped_f\n    return copy(f, *args, **kw)\n           ^^^^^^^^^^^^^^^^^^^^\n  File \"/opt/hostedtoolcache/Python/3.11.12/x64/lib/python3.11/site-packages/tenacity/__init__.py\", line 477, in __call__\n    do = self.iter(retry_state=retry_state)\n         ^^^^^^^^^^^^^^^^^^^^^^^^^^^^^^^^^^\n  File \"/opt/hostedtoolcache/Python/3.11.12/x64/lib/python3.11/site-packages/tenacity/__init__.py\", line 378, in iter\n    result = action(retry_state)\n             ^^^^^^^^^^^^^^^^^^^\n  File \"/opt/hostedtoolcache/Python/3.11.12/x64/lib/python3.11/site-packages/tenacity/__init__.py\", line 420, in exc_check\n    raise retry_exc.reraise()\n          ^^^^^^^^^^^^^^^^^^^\n  File \"/opt/hostedtoolcache/Python/3.11.12/x64/lib/python3.11/site-packages/tenacity/__init__.py\", line 187, in reraise\n    raise self.last_attempt.result()\n          ^^^^^^^^^^^^^^^^^^^^^^^^^^\n  File \"/opt/hostedtoolcache/Python/3.11.12/x64/lib/python3.11/concurrent/futures/_base.py\", line 449, in result\n    return self.__get_result()\n           ^^^^^^^^^^^^^^^^^^^\n  File \"/opt/hostedtoolcache/Python/3.11.12/x64/lib/python3.11/concurrent/futures/_base.py\", line 401, in __get_result\n    raise self._exception\n  File \"/opt/hostedtoolcache/Python/3.11.12/x64/lib/python3.11/site-packages/tenacity/__init__.py\", line 480, in __call__\n    result = fn(*args, **kwargs)\n             ^^^^^^^^^^^^^^^^^^^\n  File \"/opt/hostedtoolcache/Python/3.11.12/x64/lib/python3.11/site-packages/langchain_google_genai/chat_models.py\", line 208, in _chat_with_retry\n    raise e\n  File \"/opt/hostedtoolcache/Python/3.11.12/x64/lib/python3.11/site-packages/langchain_google_genai/chat_models.py\", line 192, in _chat_with_retry\n    return generation_method(**kwargs)\n           ^^^^^^^^^^^^^^^^^^^^^^^^^^^\n  File \"/opt/hostedtoolcache/Python/3.11.12/x64/lib/python3.11/site-packages/google/ai/generativelanguage_v1beta/services/generative_service/client.py\", line 868, in generate_content\n    response = rpc(\n               ^^^^\n  File \"/opt/hostedtoolcache/Python/3.11.12/x64/lib/python3.11/site-packages/google/api_core/gapic_v1/method.py\", line 131, in __call__\n    return wrapped_func(*args, **kwargs)\n           ^^^^^^^^^^^^^^^^^^^^^^^^^^^^^\n  File \"/opt/hostedtoolcache/Python/3.11.12/x64/lib/python3.11/site-packages/google/api_core/retry/retry_unary.py\", line 294, in retry_wrapped_func\n    return retry_target(\n           ^^^^^^^^^^^^^\n  File \"/opt/hostedtoolcache/Python/3.11.12/x64/lib/python3.11/site-packages/google/api_core/retry/retry_unary.py\", line 156, in retry_target\n    next_sleep = _retry_error_helper(\n                 ^^^^^^^^^^^^^^^^^^^^\n  File \"/opt/hostedtoolcache/Python/3.11.12/x64/lib/python3.11/site-packages/google/api_core/retry/retry_base.py\", line 214, in _retry_error_helper\n    raise final_exc from source_exc\n  File \"/opt/hostedtoolcache/Python/3.11.12/x64/lib/python3.11/site-packages/google/api_core/retry/retry_unary.py\", line 147, in retry_target\n    result = target()\n             ^^^^^^^^\n  File \"/opt/hostedtoolcache/Python/3.11.12/x64/lib/python3.11/site-packages/google/api_core/timeout.py\", line 130, in func_with_timeout\n    return func(*args, **kwargs)\n           ^^^^^^^^^^^^^^^^^^^^^\n  File \"/opt/hostedtoolcache/Python/3.11.12/x64/lib/python3.11/site-packages/google/api_core/grpc_helpers.py\", line 78, in error_remapped_callable\n    raise exceptions.from_grpc_error(exc) from exc\n","flaky":false,"newFailed":false,"newBroken":true,"newPassed":false,"retriesCount":0,"retriesStatusChange":false,"beforeStages":[],"testStage":{"status":"broken","statusMessage":"google.api_core.exceptions.ResourceExhausted: 429 You exceeded your current quota, please check your plan and billing details. For more information on this error, head to: https://ai.google.dev/gemini-api/docs/rate-limits. [violations {\n  quota_metric: \"generativelanguage.googleapis.com/generate_content_free_tier_requests\"\n  quota_id: \"GenerateRequestsPerDayPerProjectPerModel-FreeTier\"\n  quota_dimensions {\n    key: \"model\"\n    value: \"gemini-2.0-flash\"\n  }\n  quota_dimensions {\n    key: \"location\"\n    value: \"global\"\n  }\n  quota_value: 1000\n}\n, links {\n  description: \"Learn more about Gemini API quotas\"\n  url: \"https://ai.google.dev/gemini-api/docs/rate-limits\"\n}\n, retry_delay {\n  seconds: 18\n}\n]\n","statusTrace":"  File \"/opt/hostedtoolcache/Python/3.11.12/x64/lib/python3.11/site-packages/behave/model.py\", line 1329, in run\n    match.run(runner.context)\n  File \"/opt/hostedtoolcache/Python/3.11.12/x64/lib/python3.11/site-packages/behave/matchers.py\", line 98, in run\n    self.func(context, *args, **kwargs)\n  File \"features/steps/common.py\", line 20, in step_impl\n    al.do(instruction)\n  File \"/opt/hostedtoolcache/Python/3.11.12/x64/lib/python3.11/site-packages/decorator.py\", line 235, in fun\n    return caller(func, *(extras + args), **kw)\n           ^^^^^^^^^^^^^^^^^^^^^^^^^^^^^^^^^^^^\n  File \"/opt/hostedtoolcache/Python/3.11.12/x64/lib/python3.11/site-packages/retry/api.py\", line 90, in retry_decorator\n    return __retry_internal(partial(f, *args, **kwargs), exceptions, tries, delay, max_delay, backoff, jitter,\n           ^^^^^^^^^^^^^^^^^^^^^^^^^^^^^^^^^^^^^^^^^^^^^^^^^^^^^^^^^^^^^^^^^^^^^^^^^^^^^^^^^^^^^^^^^^^^^^^^^^^\n  File \"/opt/hostedtoolcache/Python/3.11.12/x64/lib/python3.11/site-packages/retry/api.py\", line 35, in __retry_internal\n    return f()\n           ^^^\n  File \"/opt/hostedtoolcache/Python/3.11.12/x64/lib/python3.11/site-packages/alumnium/alumni.py\", line 84, in do\n    steps = self.planner_agent.invoke(goal)\n            ^^^^^^^^^^^^^^^^^^^^^^^^^^^^^^^\n  File \"/opt/hostedtoolcache/Python/3.11.12/x64/lib/python3.11/site-packages/alumnium/agents/planner_agent.py\", line 54, in invoke\n    message = self.chain.invoke({\"goal\": goal, \"aria\": aria.to_xml()})\n              ^^^^^^^^^^^^^^^^^^^^^^^^^^^^^^^^^^^^^^^^^^^^^^^^^^^^^^^^\n  File \"/opt/hostedtoolcache/Python/3.11.12/x64/lib/python3.11/site-packages/langchain_core/runnables/base.py\", line 3047, in invoke\n    input_ = context.run(step.invoke, input_, config)\n             ^^^^^^^^^^^^^^^^^^^^^^^^^^^^^^^^^^^^^^^^\n  File \"/opt/hostedtoolcache/Python/3.11.12/x64/lib/python3.11/site-packages/langchain_core/runnables/retry.py\", line 201, in invoke\n    return self._call_with_config(self._invoke, input, config, **kwargs)\n           ^^^^^^^^^^^^^^^^^^^^^^^^^^^^^^^^^^^^^^^^^^^^^^^^^^^^^^^^^^^^^\n  File \"/opt/hostedtoolcache/Python/3.11.12/x64/lib/python3.11/site-packages/langchain_core/runnables/base.py\", line 1940, in _call_with_config\n    context.run(\n  File \"/opt/hostedtoolcache/Python/3.11.12/x64/lib/python3.11/site-packages/langchain_core/runnables/config.py\", line 428, in call_func_with_variable_args\n    return func(input, **kwargs)  # type: ignore[call-arg]\n           ^^^^^^^^^^^^^^^^^^^^^\n  File \"/opt/hostedtoolcache/Python/3.11.12/x64/lib/python3.11/site-packages/langchain_core/runnables/retry.py\", line 186, in _invoke\n    for attempt in self._sync_retrying(reraise=True):\n  File \"/opt/hostedtoolcache/Python/3.11.12/x64/lib/python3.11/site-packages/tenacity/__init__.py\", line 445, in __iter__\n    do = self.iter(retry_state=retry_state)\n         ^^^^^^^^^^^^^^^^^^^^^^^^^^^^^^^^^^\n  File \"/opt/hostedtoolcache/Python/3.11.12/x64/lib/python3.11/site-packages/tenacity/__init__.py\", line 378, in iter\n    result = action(retry_state)\n             ^^^^^^^^^^^^^^^^^^^\n  File \"/opt/hostedtoolcache/Python/3.11.12/x64/lib/python3.11/site-packages/tenacity/__init__.py\", line 420, in exc_check\n    raise retry_exc.reraise()\n          ^^^^^^^^^^^^^^^^^^^\n  File \"/opt/hostedtoolcache/Python/3.11.12/x64/lib/python3.11/site-packages/tenacity/__init__.py\", line 187, in reraise\n    raise self.last_attempt.result()\n          ^^^^^^^^^^^^^^^^^^^^^^^^^^\n  File \"/opt/hostedtoolcache/Python/3.11.12/x64/lib/python3.11/concurrent/futures/_base.py\", line 449, in result\n    return self.__get_result()\n           ^^^^^^^^^^^^^^^^^^^\n  File \"/opt/hostedtoolcache/Python/3.11.12/x64/lib/python3.11/concurrent/futures/_base.py\", line 401, in __get_result\n    raise self._exception\n  File \"/opt/hostedtoolcache/Python/3.11.12/x64/lib/python3.11/site-packages/langchain_core/runnables/retry.py\", line 188, in _invoke\n    result = super().invoke(\n             ^^^^^^^^^^^^^^^\n  File \"/opt/hostedtoolcache/Python/3.11.12/x64/lib/python3.11/site-packages/langchain_core/runnables/base.py\", line 5431, in invoke\n    return self.bound.invoke(\n           ^^^^^^^^^^^^^^^^^^\n  File \"/opt/hostedtoolcache/Python/3.11.12/x64/lib/python3.11/site-packages/langchain_core/runnables/retry.py\", line 201, in invoke\n    return self._call_with_config(self._invoke, input, config, **kwargs)\n           ^^^^^^^^^^^^^^^^^^^^^^^^^^^^^^^^^^^^^^^^^^^^^^^^^^^^^^^^^^^^^\n  File \"/opt/hostedtoolcache/Python/3.11.12/x64/lib/python3.11/site-packages/langchain_core/runnables/base.py\", line 1940, in _call_with_config\n    context.run(\n  File \"/opt/hostedtoolcache/Python/3.11.12/x64/lib/python3.11/site-packages/langchain_core/runnables/config.py\", line 428, in call_func_with_variable_args\n    return func(input, **kwargs)  # type: ignore[call-arg]\n           ^^^^^^^^^^^^^^^^^^^^^\n  File \"/opt/hostedtoolcache/Python/3.11.12/x64/lib/python3.11/site-packages/langchain_core/runnables/retry.py\", line 186, in _invoke\n    for attempt in self._sync_retrying(reraise=True):\n  File \"/opt/hostedtoolcache/Python/3.11.12/x64/lib/python3.11/site-packages/tenacity/__init__.py\", line 445, in __iter__\n    do = self.iter(retry_state=retry_state)\n         ^^^^^^^^^^^^^^^^^^^^^^^^^^^^^^^^^^\n  File \"/opt/hostedtoolcache/Python/3.11.12/x64/lib/python3.11/site-packages/tenacity/__init__.py\", line 378, in iter\n    result = action(retry_state)\n             ^^^^^^^^^^^^^^^^^^^\n  File \"/opt/hostedtoolcache/Python/3.11.12/x64/lib/python3.11/site-packages/tenacity/__init__.py\", line 400, in <lambda>\n    self._add_action_func(lambda rs: rs.outcome.result())\n                                     ^^^^^^^^^^^^^^^^^^^\n  File \"/opt/hostedtoolcache/Python/3.11.12/x64/lib/python3.11/concurrent/futures/_base.py\", line 449, in result\n    return self.__get_result()\n           ^^^^^^^^^^^^^^^^^^^\n  File \"/opt/hostedtoolcache/Python/3.11.12/x64/lib/python3.11/concurrent/futures/_base.py\", line 401, in __get_result\n    raise self._exception\n  File \"/opt/hostedtoolcache/Python/3.11.12/x64/lib/python3.11/site-packages/langchain_core/runnables/retry.py\", line 188, in _invoke\n    result = super().invoke(\n             ^^^^^^^^^^^^^^^\n  File \"/opt/hostedtoolcache/Python/3.11.12/x64/lib/python3.11/site-packages/langchain_core/runnables/base.py\", line 5431, in invoke\n    return self.bound.invoke(\n           ^^^^^^^^^^^^^^^^^^\n  File \"/opt/hostedtoolcache/Python/3.11.12/x64/lib/python3.11/site-packages/langchain_google_genai/chat_models.py\", line 1255, in invoke\n    return super().invoke(input, config, stop=stop, **kwargs)\n           ^^^^^^^^^^^^^^^^^^^^^^^^^^^^^^^^^^^^^^^^^^^^^^^^^^\n  File \"/opt/hostedtoolcache/Python/3.11.12/x64/lib/python3.11/site-packages/langchain_core/language_models/chat_models.py\", line 372, in invoke\n    self.generate_prompt(\n  File \"/opt/hostedtoolcache/Python/3.11.12/x64/lib/python3.11/site-packages/langchain_core/language_models/chat_models.py\", line 957, in generate_prompt\n    return self.generate(prompt_messages, stop=stop, callbacks=callbacks, **kwargs)\n           ^^^^^^^^^^^^^^^^^^^^^^^^^^^^^^^^^^^^^^^^^^^^^^^^^^^^^^^^^^^^^^^^^^^^^^^^\n  File \"/opt/hostedtoolcache/Python/3.11.12/x64/lib/python3.11/site-packages/langchain_core/language_models/chat_models.py\", line 776, in generate\n    self._generate_with_cache(\n  File \"/opt/hostedtoolcache/Python/3.11.12/x64/lib/python3.11/site-packages/langchain_core/language_models/chat_models.py\", line 1022, in _generate_with_cache\n    result = self._generate(\n             ^^^^^^^^^^^^^^^\n  File \"/opt/hostedtoolcache/Python/3.11.12/x64/lib/python3.11/site-packages/langchain_google_genai/chat_models.py\", line 1342, in _generate\n    response: GenerateContentResponse = _chat_with_retry(\n                                        ^^^^^^^^^^^^^^^^^\n  File \"/opt/hostedtoolcache/Python/3.11.12/x64/lib/python3.11/site-packages/langchain_google_genai/chat_models.py\", line 210, in _chat_with_retry\n    return _chat_with_retry(**kwargs)\n           ^^^^^^^^^^^^^^^^^^^^^^^^^^\n  File \"/opt/hostedtoolcache/Python/3.11.12/x64/lib/python3.11/site-packages/tenacity/__init__.py\", line 338, in wrapped_f\n    return copy(f, *args, **kw)\n           ^^^^^^^^^^^^^^^^^^^^\n  File \"/opt/hostedtoolcache/Python/3.11.12/x64/lib/python3.11/site-packages/tenacity/__init__.py\", line 477, in __call__\n    do = self.iter(retry_state=retry_state)\n         ^^^^^^^^^^^^^^^^^^^^^^^^^^^^^^^^^^\n  File \"/opt/hostedtoolcache/Python/3.11.12/x64/lib/python3.11/site-packages/tenacity/__init__.py\", line 378, in iter\n    result = action(retry_state)\n             ^^^^^^^^^^^^^^^^^^^\n  File \"/opt/hostedtoolcache/Python/3.11.12/x64/lib/python3.11/site-packages/tenacity/__init__.py\", line 420, in exc_check\n    raise retry_exc.reraise()\n          ^^^^^^^^^^^^^^^^^^^\n  File \"/opt/hostedtoolcache/Python/3.11.12/x64/lib/python3.11/site-packages/tenacity/__init__.py\", line 187, in reraise\n    raise self.last_attempt.result()\n          ^^^^^^^^^^^^^^^^^^^^^^^^^^\n  File \"/opt/hostedtoolcache/Python/3.11.12/x64/lib/python3.11/concurrent/futures/_base.py\", line 449, in result\n    return self.__get_result()\n           ^^^^^^^^^^^^^^^^^^^\n  File \"/opt/hostedtoolcache/Python/3.11.12/x64/lib/python3.11/concurrent/futures/_base.py\", line 401, in __get_result\n    raise self._exception\n  File \"/opt/hostedtoolcache/Python/3.11.12/x64/lib/python3.11/site-packages/tenacity/__init__.py\", line 480, in __call__\n    result = fn(*args, **kwargs)\n             ^^^^^^^^^^^^^^^^^^^\n  File \"/opt/hostedtoolcache/Python/3.11.12/x64/lib/python3.11/site-packages/langchain_google_genai/chat_models.py\", line 208, in _chat_with_retry\n    raise e\n  File \"/opt/hostedtoolcache/Python/3.11.12/x64/lib/python3.11/site-packages/langchain_google_genai/chat_models.py\", line 192, in _chat_with_retry\n    return generation_method(**kwargs)\n           ^^^^^^^^^^^^^^^^^^^^^^^^^^^\n  File \"/opt/hostedtoolcache/Python/3.11.12/x64/lib/python3.11/site-packages/google/ai/generativelanguage_v1beta/services/generative_service/client.py\", line 868, in generate_content\n    response = rpc(\n               ^^^^\n  File \"/opt/hostedtoolcache/Python/3.11.12/x64/lib/python3.11/site-packages/google/api_core/gapic_v1/method.py\", line 131, in __call__\n    return wrapped_func(*args, **kwargs)\n           ^^^^^^^^^^^^^^^^^^^^^^^^^^^^^\n  File \"/opt/hostedtoolcache/Python/3.11.12/x64/lib/python3.11/site-packages/google/api_core/retry/retry_unary.py\", line 294, in retry_wrapped_func\n    return retry_target(\n           ^^^^^^^^^^^^^\n  File \"/opt/hostedtoolcache/Python/3.11.12/x64/lib/python3.11/site-packages/google/api_core/retry/retry_unary.py\", line 156, in retry_target\n    next_sleep = _retry_error_helper(\n                 ^^^^^^^^^^^^^^^^^^^^\n  File \"/opt/hostedtoolcache/Python/3.11.12/x64/lib/python3.11/site-packages/google/api_core/retry/retry_base.py\", line 214, in _retry_error_helper\n    raise final_exc from source_exc\n  File \"/opt/hostedtoolcache/Python/3.11.12/x64/lib/python3.11/site-packages/google/api_core/retry/retry_unary.py\", line 147, in retry_target\n    result = target()\n             ^^^^^^^^\n  File \"/opt/hostedtoolcache/Python/3.11.12/x64/lib/python3.11/site-packages/google/api_core/timeout.py\", line 130, in func_with_timeout\n    return func(*args, **kwargs)\n           ^^^^^^^^^^^^^^^^^^^^^\n  File \"/opt/hostedtoolcache/Python/3.11.12/x64/lib/python3.11/site-packages/google/api_core/grpc_helpers.py\", line 78, in error_remapped_callable\n    raise exceptions.from_grpc_error(exc) from exc\n","steps":[{"name":"Given I am on the home page","time":{"start":1750619202538,"stop":1750619204680,"duration":2142},"status":"passed","steps":[],"attachments":[],"parameters":[],"shouldDisplayMessage":false,"stepsCount":0,"attachmentsCount":0,"hasContent":false,"attachmentStep":false},{"name":"When \"I click on 'Add to cart' button of product 'Album'\"","time":{"start":1750619204680,"stop":1750619205584,"duration":904},"status":"passed","steps":[],"attachments":[],"parameters":[],"shouldDisplayMessage":false,"stepsCount":0,"attachmentsCount":0,"hasContent":false,"attachmentStep":false},{"name":"And I click on the 'View cart' button","time":{"start":1750619205584,"stop":1750619207156,"duration":1572},"status":"passed","steps":[],"attachments":[],"parameters":[],"shouldDisplayMessage":false,"stepsCount":0,"attachmentsCount":0,"hasContent":false,"attachmentStep":false},{"name":"When \"I change the quantity of 'Album' to 2\"","time":{"start":1750619207156,"stop":1750620281914,"duration":1074758},"status":"broken","statusMessage":"google.api_core.exceptions.ResourceExhausted: 429 You exceeded your current quota, please check your plan and billing details. For more information on this error, head to: https://ai.google.dev/gemini-api/docs/rate-limits. [violations {\n  quota_metric: \"generativelanguage.googleapis.com/generate_content_free_tier_requests\"\n  quota_id: \"GenerateRequestsPerDayPerProjectPerModel-FreeTier\"\n  quota_dimensions {\n    key: \"model\"\n    value: \"gemini-2.0-flash\"\n  }\n  quota_dimensions {\n    key: \"location\"\n    value: \"global\"\n  }\n  quota_value: 1000\n}\n, links {\n  description: \"Learn more about Gemini API quotas\"\n  url: \"https://ai.google.dev/gemini-api/docs/rate-limits\"\n}\n, retry_delay {\n  seconds: 18\n}\n]\n","statusTrace":"  File \"/opt/hostedtoolcache/Python/3.11.12/x64/lib/python3.11/site-packages/behave/model.py\", line 1329, in run\n    match.run(runner.context)\n  File \"/opt/hostedtoolcache/Python/3.11.12/x64/lib/python3.11/site-packages/behave/matchers.py\", line 98, in run\n    self.func(context, *args, **kwargs)\n  File \"features/steps/common.py\", line 20, in step_impl\n    al.do(instruction)\n  File \"/opt/hostedtoolcache/Python/3.11.12/x64/lib/python3.11/site-packages/decorator.py\", line 235, in fun\n    return caller(func, *(extras + args), **kw)\n           ^^^^^^^^^^^^^^^^^^^^^^^^^^^^^^^^^^^^\n  File \"/opt/hostedtoolcache/Python/3.11.12/x64/lib/python3.11/site-packages/retry/api.py\", line 90, in retry_decorator\n    return __retry_internal(partial(f, *args, **kwargs), exceptions, tries, delay, max_delay, backoff, jitter,\n           ^^^^^^^^^^^^^^^^^^^^^^^^^^^^^^^^^^^^^^^^^^^^^^^^^^^^^^^^^^^^^^^^^^^^^^^^^^^^^^^^^^^^^^^^^^^^^^^^^^^\n  File \"/opt/hostedtoolcache/Python/3.11.12/x64/lib/python3.11/site-packages/retry/api.py\", line 35, in __retry_internal\n    return f()\n           ^^^\n  File \"/opt/hostedtoolcache/Python/3.11.12/x64/lib/python3.11/site-packages/alumnium/alumni.py\", line 84, in do\n    steps = self.planner_agent.invoke(goal)\n            ^^^^^^^^^^^^^^^^^^^^^^^^^^^^^^^\n  File \"/opt/hostedtoolcache/Python/3.11.12/x64/lib/python3.11/site-packages/alumnium/agents/planner_agent.py\", line 54, in invoke\n    message = self.chain.invoke({\"goal\": goal, \"aria\": aria.to_xml()})\n              ^^^^^^^^^^^^^^^^^^^^^^^^^^^^^^^^^^^^^^^^^^^^^^^^^^^^^^^^\n  File \"/opt/hostedtoolcache/Python/3.11.12/x64/lib/python3.11/site-packages/langchain_core/runnables/base.py\", line 3047, in invoke\n    input_ = context.run(step.invoke, input_, config)\n             ^^^^^^^^^^^^^^^^^^^^^^^^^^^^^^^^^^^^^^^^\n  File \"/opt/hostedtoolcache/Python/3.11.12/x64/lib/python3.11/site-packages/langchain_core/runnables/retry.py\", line 201, in invoke\n    return self._call_with_config(self._invoke, input, config, **kwargs)\n           ^^^^^^^^^^^^^^^^^^^^^^^^^^^^^^^^^^^^^^^^^^^^^^^^^^^^^^^^^^^^^\n  File \"/opt/hostedtoolcache/Python/3.11.12/x64/lib/python3.11/site-packages/langchain_core/runnables/base.py\", line 1940, in _call_with_config\n    context.run(\n  File \"/opt/hostedtoolcache/Python/3.11.12/x64/lib/python3.11/site-packages/langchain_core/runnables/config.py\", line 428, in call_func_with_variable_args\n    return func(input, **kwargs)  # type: ignore[call-arg]\n           ^^^^^^^^^^^^^^^^^^^^^\n  File \"/opt/hostedtoolcache/Python/3.11.12/x64/lib/python3.11/site-packages/langchain_core/runnables/retry.py\", line 186, in _invoke\n    for attempt in self._sync_retrying(reraise=True):\n  File \"/opt/hostedtoolcache/Python/3.11.12/x64/lib/python3.11/site-packages/tenacity/__init__.py\", line 445, in __iter__\n    do = self.iter(retry_state=retry_state)\n         ^^^^^^^^^^^^^^^^^^^^^^^^^^^^^^^^^^\n  File \"/opt/hostedtoolcache/Python/3.11.12/x64/lib/python3.11/site-packages/tenacity/__init__.py\", line 378, in iter\n    result = action(retry_state)\n             ^^^^^^^^^^^^^^^^^^^\n  File \"/opt/hostedtoolcache/Python/3.11.12/x64/lib/python3.11/site-packages/tenacity/__init__.py\", line 420, in exc_check\n    raise retry_exc.reraise()\n          ^^^^^^^^^^^^^^^^^^^\n  File \"/opt/hostedtoolcache/Python/3.11.12/x64/lib/python3.11/site-packages/tenacity/__init__.py\", line 187, in reraise\n    raise self.last_attempt.result()\n          ^^^^^^^^^^^^^^^^^^^^^^^^^^\n  File \"/opt/hostedtoolcache/Python/3.11.12/x64/lib/python3.11/concurrent/futures/_base.py\", line 449, in result\n    return self.__get_result()\n           ^^^^^^^^^^^^^^^^^^^\n  File \"/opt/hostedtoolcache/Python/3.11.12/x64/lib/python3.11/concurrent/futures/_base.py\", line 401, in __get_result\n    raise self._exception\n  File \"/opt/hostedtoolcache/Python/3.11.12/x64/lib/python3.11/site-packages/langchain_core/runnables/retry.py\", line 188, in _invoke\n    result = super().invoke(\n             ^^^^^^^^^^^^^^^\n  File \"/opt/hostedtoolcache/Python/3.11.12/x64/lib/python3.11/site-packages/langchain_core/runnables/base.py\", line 5431, in invoke\n    return self.bound.invoke(\n           ^^^^^^^^^^^^^^^^^^\n  File \"/opt/hostedtoolcache/Python/3.11.12/x64/lib/python3.11/site-packages/langchain_core/runnables/retry.py\", line 201, in invoke\n    return self._call_with_config(self._invoke, input, config, **kwargs)\n           ^^^^^^^^^^^^^^^^^^^^^^^^^^^^^^^^^^^^^^^^^^^^^^^^^^^^^^^^^^^^^\n  File \"/opt/hostedtoolcache/Python/3.11.12/x64/lib/python3.11/site-packages/langchain_core/runnables/base.py\", line 1940, in _call_with_config\n    context.run(\n  File \"/opt/hostedtoolcache/Python/3.11.12/x64/lib/python3.11/site-packages/langchain_core/runnables/config.py\", line 428, in call_func_with_variable_args\n    return func(input, **kwargs)  # type: ignore[call-arg]\n           ^^^^^^^^^^^^^^^^^^^^^\n  File \"/opt/hostedtoolcache/Python/3.11.12/x64/lib/python3.11/site-packages/langchain_core/runnables/retry.py\", line 186, in _invoke\n    for attempt in self._sync_retrying(reraise=True):\n  File \"/opt/hostedtoolcache/Python/3.11.12/x64/lib/python3.11/site-packages/tenacity/__init__.py\", line 445, in __iter__\n    do = self.iter(retry_state=retry_state)\n         ^^^^^^^^^^^^^^^^^^^^^^^^^^^^^^^^^^\n  File \"/opt/hostedtoolcache/Python/3.11.12/x64/lib/python3.11/site-packages/tenacity/__init__.py\", line 378, in iter\n    result = action(retry_state)\n             ^^^^^^^^^^^^^^^^^^^\n  File \"/opt/hostedtoolcache/Python/3.11.12/x64/lib/python3.11/site-packages/tenacity/__init__.py\", line 400, in <lambda>\n    self._add_action_func(lambda rs: rs.outcome.result())\n                                     ^^^^^^^^^^^^^^^^^^^\n  File \"/opt/hostedtoolcache/Python/3.11.12/x64/lib/python3.11/concurrent/futures/_base.py\", line 449, in result\n    return self.__get_result()\n           ^^^^^^^^^^^^^^^^^^^\n  File \"/opt/hostedtoolcache/Python/3.11.12/x64/lib/python3.11/concurrent/futures/_base.py\", line 401, in __get_result\n    raise self._exception\n  File \"/opt/hostedtoolcache/Python/3.11.12/x64/lib/python3.11/site-packages/langchain_core/runnables/retry.py\", line 188, in _invoke\n    result = super().invoke(\n             ^^^^^^^^^^^^^^^\n  File \"/opt/hostedtoolcache/Python/3.11.12/x64/lib/python3.11/site-packages/langchain_core/runnables/base.py\", line 5431, in invoke\n    return self.bound.invoke(\n           ^^^^^^^^^^^^^^^^^^\n  File \"/opt/hostedtoolcache/Python/3.11.12/x64/lib/python3.11/site-packages/langchain_google_genai/chat_models.py\", line 1255, in invoke\n    return super().invoke(input, config, stop=stop, **kwargs)\n           ^^^^^^^^^^^^^^^^^^^^^^^^^^^^^^^^^^^^^^^^^^^^^^^^^^\n  File \"/opt/hostedtoolcache/Python/3.11.12/x64/lib/python3.11/site-packages/langchain_core/language_models/chat_models.py\", line 372, in invoke\n    self.generate_prompt(\n  File \"/opt/hostedtoolcache/Python/3.11.12/x64/lib/python3.11/site-packages/langchain_core/language_models/chat_models.py\", line 957, in generate_prompt\n    return self.generate(prompt_messages, stop=stop, callbacks=callbacks, **kwargs)\n           ^^^^^^^^^^^^^^^^^^^^^^^^^^^^^^^^^^^^^^^^^^^^^^^^^^^^^^^^^^^^^^^^^^^^^^^^\n  File \"/opt/hostedtoolcache/Python/3.11.12/x64/lib/python3.11/site-packages/langchain_core/language_models/chat_models.py\", line 776, in generate\n    self._generate_with_cache(\n  File \"/opt/hostedtoolcache/Python/3.11.12/x64/lib/python3.11/site-packages/langchain_core/language_models/chat_models.py\", line 1022, in _generate_with_cache\n    result = self._generate(\n             ^^^^^^^^^^^^^^^\n  File \"/opt/hostedtoolcache/Python/3.11.12/x64/lib/python3.11/site-packages/langchain_google_genai/chat_models.py\", line 1342, in _generate\n    response: GenerateContentResponse = _chat_with_retry(\n                                        ^^^^^^^^^^^^^^^^^\n  File \"/opt/hostedtoolcache/Python/3.11.12/x64/lib/python3.11/site-packages/langchain_google_genai/chat_models.py\", line 210, in _chat_with_retry\n    return _chat_with_retry(**kwargs)\n           ^^^^^^^^^^^^^^^^^^^^^^^^^^\n  File \"/opt/hostedtoolcache/Python/3.11.12/x64/lib/python3.11/site-packages/tenacity/__init__.py\", line 338, in wrapped_f\n    return copy(f, *args, **kw)\n           ^^^^^^^^^^^^^^^^^^^^\n  File \"/opt/hostedtoolcache/Python/3.11.12/x64/lib/python3.11/site-packages/tenacity/__init__.py\", line 477, in __call__\n    do = self.iter(retry_state=retry_state)\n         ^^^^^^^^^^^^^^^^^^^^^^^^^^^^^^^^^^\n  File \"/opt/hostedtoolcache/Python/3.11.12/x64/lib/python3.11/site-packages/tenacity/__init__.py\", line 378, in iter\n    result = action(retry_state)\n             ^^^^^^^^^^^^^^^^^^^\n  File \"/opt/hostedtoolcache/Python/3.11.12/x64/lib/python3.11/site-packages/tenacity/__init__.py\", line 420, in exc_check\n    raise retry_exc.reraise()\n          ^^^^^^^^^^^^^^^^^^^\n  File \"/opt/hostedtoolcache/Python/3.11.12/x64/lib/python3.11/site-packages/tenacity/__init__.py\", line 187, in reraise\n    raise self.last_attempt.result()\n          ^^^^^^^^^^^^^^^^^^^^^^^^^^\n  File \"/opt/hostedtoolcache/Python/3.11.12/x64/lib/python3.11/concurrent/futures/_base.py\", line 449, in result\n    return self.__get_result()\n           ^^^^^^^^^^^^^^^^^^^\n  File \"/opt/hostedtoolcache/Python/3.11.12/x64/lib/python3.11/concurrent/futures/_base.py\", line 401, in __get_result\n    raise self._exception\n  File \"/opt/hostedtoolcache/Python/3.11.12/x64/lib/python3.11/site-packages/tenacity/__init__.py\", line 480, in __call__\n    result = fn(*args, **kwargs)\n             ^^^^^^^^^^^^^^^^^^^\n  File \"/opt/hostedtoolcache/Python/3.11.12/x64/lib/python3.11/site-packages/langchain_google_genai/chat_models.py\", line 208, in _chat_with_retry\n    raise e\n  File \"/opt/hostedtoolcache/Python/3.11.12/x64/lib/python3.11/site-packages/langchain_google_genai/chat_models.py\", line 192, in _chat_with_retry\n    return generation_method(**kwargs)\n           ^^^^^^^^^^^^^^^^^^^^^^^^^^^\n  File \"/opt/hostedtoolcache/Python/3.11.12/x64/lib/python3.11/site-packages/google/ai/generativelanguage_v1beta/services/generative_service/client.py\", line 868, in generate_content\n    response = rpc(\n               ^^^^\n  File \"/opt/hostedtoolcache/Python/3.11.12/x64/lib/python3.11/site-packages/google/api_core/gapic_v1/method.py\", line 131, in __call__\n    return wrapped_func(*args, **kwargs)\n           ^^^^^^^^^^^^^^^^^^^^^^^^^^^^^\n  File \"/opt/hostedtoolcache/Python/3.11.12/x64/lib/python3.11/site-packages/google/api_core/retry/retry_unary.py\", line 294, in retry_wrapped_func\n    return retry_target(\n           ^^^^^^^^^^^^^\n  File \"/opt/hostedtoolcache/Python/3.11.12/x64/lib/python3.11/site-packages/google/api_core/retry/retry_unary.py\", line 156, in retry_target\n    next_sleep = _retry_error_helper(\n                 ^^^^^^^^^^^^^^^^^^^^\n  File \"/opt/hostedtoolcache/Python/3.11.12/x64/lib/python3.11/site-packages/google/api_core/retry/retry_base.py\", line 214, in _retry_error_helper\n    raise final_exc from source_exc\n  File \"/opt/hostedtoolcache/Python/3.11.12/x64/lib/python3.11/site-packages/google/api_core/retry/retry_unary.py\", line 147, in retry_target\n    result = target()\n             ^^^^^^^^\n  File \"/opt/hostedtoolcache/Python/3.11.12/x64/lib/python3.11/site-packages/google/api_core/timeout.py\", line 130, in func_with_timeout\n    return func(*args, **kwargs)\n           ^^^^^^^^^^^^^^^^^^^^^\n  File \"/opt/hostedtoolcache/Python/3.11.12/x64/lib/python3.11/site-packages/google/api_core/grpc_helpers.py\", line 78, in error_remapped_callable\n    raise exceptions.from_grpc_error(exc) from exc\n","steps":[],"attachments":[],"parameters":[],"shouldDisplayMessage":true,"stepsCount":0,"attachmentsCount":0,"hasContent":true,"attachmentStep":false},{"name":"And \"I click the 'Update cart' button\"","time":{"start":1750620333517,"stop":1750620333517,"duration":0},"status":"skipped","steps":[],"attachments":[],"parameters":[],"shouldDisplayMessage":false,"stepsCount":0,"attachmentsCount":0,"hasContent":false,"attachmentStep":false},{"name":"Then I see that \"a green banner shows that cart was updated\"","time":{"start":1750620333517,"stop":1750620333517,"duration":0},"status":"skipped","steps":[],"attachments":[],"parameters":[],"shouldDisplayMessage":false,"stepsCount":0,"attachmentsCount":0,"hasContent":false,"attachmentStep":false},{"name":"And \"the updated quantity of 'Album' is 2\"","time":{"start":1750620333518,"stop":1750620333518,"duration":0},"status":"skipped","steps":[],"attachments":[],"parameters":[],"shouldDisplayMessage":false,"stepsCount":0,"attachmentsCount":0,"hasContent":false,"attachmentStep":false},{"name":"And \"the updated subtotal is 30.00 EUR\"","time":{"start":1750620333518,"stop":1750620333518,"duration":0},"status":"skipped","steps":[],"attachments":[],"parameters":[],"shouldDisplayMessage":false,"stepsCount":0,"attachmentsCount":0,"hasContent":false,"attachmentStep":false}],"attachments":[{"uid":"1d880e36d8820e61","name":"Screenshot","source":"1d880e36d8820e61.png","type":"image/png","size":49398},{"uid":"2e7cdf82c084fed2","name":"Playwright Trace","source":"2e7cdf82c084fed2.attach","type":"application/zip","size":1253944},{"uid":"75f2840bbab7dc24","name":"Video","source":"75f2840bbab7dc24.webm","type":"video/webm","size":262144}],"parameters":[],"shouldDisplayMessage":false,"stepsCount":8,"attachmentsCount":3,"hasContent":true,"attachmentStep":false},"afterStages":[],"labels":[{"name":"severity","value":"normal"},{"name":"feature","value":"cart page"},{"name":"framework","value":"behave"},{"name":"language","value":"cpython3"},{"name":"resultFormat","value":"allure2"}],"parameters":[],"links":[],"hidden":false,"retry":false,"extra":{"severity":"normal","retries":[],"categories":[{"name":"Test defects","matchedStatuses":[]}],"history":{"statistic":{"failed":1,"broken":1,"skipped":0,"passed":8,"unknown":0,"total":10},"items":[{"uid":"e8b31c8802c1e67c","status":"passed","time":{"start":1750613821088,"stop":1750613882482,"duration":61394}},{"uid":"ad545af212c43cbc","status":"passed","time":{"start":1750612798074,"stop":1750612811822,"duration":13748}},{"uid":"27aed06a7d234fa7","status":"passed","time":{"start":1750611175404,"stop":1750611195478,"duration":20074}},{"uid":"9423959964e11587","status":"passed","time":{"start":1750609544898,"stop":1750609563496,"duration":18598}},{"uid":"d671d3160b11a998","status":"passed","time":{"start":1750607482948,"stop":1750607502340,"duration":19392}},{"uid":"94c23801361d032d","status":"passed","time":{"start":1750606312931,"stop":1750606332056,"duration":19125}},{"uid":"4c749bf643dc651f","status":"passed","time":{"start":1750605643126,"stop":1750605662335,"duration":19209}},{"uid":"cc1a5b99430361cc","status":"passed","time":{"start":1750604512450,"stop":1750604532347,"duration":19897}},{"uid":"f312737a835a17ba","status":"failed","statusDetails":"AssertionError: The image and OCR text do not show a green banner indicating that the cart was updated. Therefore, the statement is false.\n","time":{"start":1750603539720,"stop":1750603555013,"duration":15293}}]},"tags":[]},"source":"b9da68a866cbb8f3.json","parameterValues":[]}